<?xml version="1.0" encoding="UTF-8"?>
<!-- Generated by org.testng.reporters.JUnitReportReporter -->
<testsuite hostname="DESKTOP-6DRS0JN" failures="0" tests="4" name="org.quote.deskTopMDATests.CarInsuranceCompanies" time="863.593" errors="1" timestamp="1 Mar 2022 21:04:17 GMT">
  <testcase classname="org.quote.deskTopMDATests.CarInsuranceCompanies" name="validate_SiteURLs" time="196.942">
    <error message="Exception occured : " type="java.lang.AssertionError">
      <![CDATA[java.lang.AssertionError: Exception occured : 
	at org.testng.Assert.fail(Assert.java:83)
	at org.quote.deskTopMDATests.CarInsuranceCompanies.validate_SiteURLs(CarInsuranceCompanies.java:73)
	at java.base/jdk.internal.reflect.NativeMethodAccessorImpl.invoke0(Native Method)
	at java.base/jdk.internal.reflect.NativeMethodAccessorImpl.invoke(NativeMethodAccessorImpl.java:78)
	at java.base/jdk.internal.reflect.DelegatingMethodAccessorImpl.invoke(DelegatingMethodAccessorImpl.java:43)
	at java.base/java.lang.reflect.Method.invoke(Method.java:567)
	at org.testng.internal.MethodInvocationHelper.invokeMethod(MethodInvocationHelper.java:80)
	at org.testng.internal.Invoker.invokeMethod(Invoker.java:714)
	at org.testng.internal.Invoker.invokeTestMethod(Invoker.java:901)
	at org.testng.internal.Invoker.invokeTestMethods(Invoker.java:1231)
	at org.testng.internal.TestMethodWorker.invokeTestMethods(TestMethodWorker.java:127)
	at org.testng.internal.TestMethodWorker.run(TestMethodWorker.java:111)
	at org.testng.TestRunner.privateRun(TestRunner.java:767)
	at org.testng.TestRunner.run(TestRunner.java:617)
	at org.testng.SuiteRunner.runTest(SuiteRunner.java:334)
	at org.testng.SuiteRunner.runSequentially(SuiteRunner.java:329)
	at org.testng.SuiteRunner.privateRun(SuiteRunner.java:291)
	at org.testng.SuiteRunner.run(SuiteRunner.java:240)
	at org.testng.SuiteRunnerWorker.runSuite(SuiteRunnerWorker.java:52)
	at org.testng.SuiteRunnerWorker.run(SuiteRunnerWorker.java:86)
	at org.testng.TestNG.runSuitesSequentially(TestNG.java:1198)
	at org.testng.TestNG.runSuitesLocally(TestNG.java:1123)
	at org.testng.TestNG.run(TestNG.java:1031)
	at org.testng.remote.AbstractRemoteTestNG.run(AbstractRemoteTestNG.java:115)
	at org.testng.remote.RemoteTestNG.initAndRun(RemoteTestNG.java:251)
	at org.testng.remote.RemoteTestNG.main(RemoteTestNG.java:77)
Caused by: java.lang.IndexOutOfBoundsException: Index 1 out of bounds for length 1
	at java.base/jdk.internal.util.Preconditions.outOfBounds(Preconditions.java:64)
	at java.base/jdk.internal.util.Preconditions.outOfBoundsCheckIndex(Preconditions.java:70)
	at java.base/jdk.internal.util.Preconditions.checkIndex(Preconditions.java:266)
	at java.base/java.util.Objects.checkIndex(Objects.java:359)
	at java.base/java.util.ArrayList.get(ArrayList.java:427)
	at org.quote.MdaTypes.ProcessMda.processTopMDA(ProcessMda.java:209)
	at org.quote.deskTopMDATests.CarInsuranceCompanies.validate_TopMDA(CarInsuranceCompanies.java:99)
	at org.quote.deskTopMDATests.CarInsuranceCompanies.validate_SiteURLs(CarInsuranceCompanies.java:52)
	... 24 more
]]>
    </error>
  </testcase> <!-- validate_SiteURLs -->
  <testcase classname="org.quote.deskTopMDATests.CarInsuranceCompanies" name="validate_SiteURLs" time="232.875"/>
  <testcase classname="org.quote.deskTopMDATests.CarInsuranceCompanies" name="validate_SiteURLs" time="211.565"/>
  <testcase classname="org.quote.deskTopMDATests.CarInsuranceCompanies" name="validate_SiteURLs" time="222.211"/>
</testsuite> <!-- org.quote.deskTopMDATests.CarInsuranceCompanies -->
